Workbook
Name Tabel_SUSUT_CABE: 'CABE PER RESEP'!$A$159:$AG$172
Name TanggalMulai: _PERIODE!$C$5

Sheet DATA BASE pastikan sesuai riil
A1: NAMA BARANG | B1: KODE BARANG | C1: ITEM STOCK OPNAME | D1: SATUAN | E1: Konversi | F1: SATUAN 2 | G1: INPUT SO HARIAN | H1: INPUT BARANG MASUK/KELUAR | I1: LINK | J1: Helper | K1: KATEGORI | L1: STATUS | M1: BOM [Promix 00 & 04] | N1: Cancel Nota [Waste CN Dine In & TA] | O1: Trial Porsi [Trial Porsi] | P1: Waste Handling [Waste Handling]
A2: ADONAN GORENG MEKAR | C2: Adonan Goreng Mekar (karton) | D2: karton | E2: 15000 | F2: gr | G2: YA | H2: YA | K2: COM DEVIASI - RESTO | L2: DEVIASI | M2: TRUE | N2: TRUE | O2: TRUE | P2: TRUE
A3: ADONAN GORENG MEKAR | C3: Adonan Goreng Mekar (pack) | D3: pack | E3: 1000 | F3: gr | G3: YA | H3: YA | K3: COM DEVIASI - RESTO | L3: DEVIASI | M3: TRUE | N3: TRUE | O3: TRUE | P3: TRUE
A4: ADONAN GORENG MEKAR | C4: Adonan Goreng Mekar (gr) | D4: gr | E4: 1 | F4: gr | G4: YA | H4: YA | K4: COM DEVIASI - RESTO | L4: DEVIASI | M4: TRUE | N4: TRUE | O4: TRUE | P4: TRUE
A5: ADONAN GORENG MEKAR | C5: Adonan Goreng Mekar dari Goreng Mekar | D5: gr | E5: 17 | F5: gr | G5: TIDAK | H5: TIDAK | I5: Sisa Goreng Mekar (Pcs) | J5: HIDE | K5: COM DEVIASI - RESTO | L5: DEVIASI | M5: TRUE | N5: TRUE | O5: TRUE | P5: TRUE
A6: ADONAN GORENG MEKAR | B6: 100434 | C6: ADONAN GORENG MEKAR | D6: GR | G6: YA | H6: YA | K6: COM DEVIASI - RESTO | L6: DEVIASI | M6: TRUE | N6: TRUE | O6: TRUE | P6: TRUE
A7: AIR MINERAL BOTOL (V.20) | C7: stok air mineral kardus utuh (karton) | D7: karton | E7: 24 | F7: botol | G7: YA | H7: YA | K7: COM DEVIASI - RESTO | L7: DEVIASI | M7: TRUE | N7: TRUE | O7: TRUE | P7: TRUE
A8: AIR MINERAL BOTOL (V.20) | C8: sisa air mineral botol (botol) | D8: botol | E8: 1 | F8: botol | G8: YA | H8: YA | K8: COM DEVIASI - RESTO | L8: DEVIASI | M8: TRUE | N8: TRUE | O8: TRUE | P8: TRUE
A9: AIR MINERAL BOTOL (V.20) | B9: 100210 | C9: AIR MINERAL BOTOL (V.20) | D9: BOTOL | G9: YA | H9: YA | K9: COM DEVIASI - RESTO | L9: DEVIASI | M9: TRUE | N9: TRUE | O9: TRUE | P9: TRUE
A10: ARANG BAKARAN | C10: Arang Bakaran (karton) | D10: karton | E10: 10000 | F10: gr | G10: YA | H10: YA | K10: COM CONSUME - RESTO | L10: USAGE | M10: N/A | N10: N/A | O10: N/A | P10: N/A
A11: ARANG BAKARAN | C11: Arang Bakaran (gr) | D11: gr | E11: 1 | F11: gr | G11: YA | H11: YA | K11: COM CONSUME - RESTO | L11: USAGE | M11: N/A | N11: N/A | O11: N/A | P11: N/A
A12: ARANG BAKARAN | B12: 100351 | C12: ARANG BAKARAN | D12: GR | G12: YA | H12: YA | K12: COM CONSUME - RESTO | L12: USAGE | M12: N/A | N12: N/A | O12: N/A | P12: N/A
A13: AYAM KECAP | C13: Ayam Kecap (karton) | D13: karton | E13: 12000 | F13: gr | G13: YA | H13: YA | K13: COM DEVIASI - RESTO | L13: DEVIASI | M13: N/A | N13: N/A | O13: N/A | P13: N/A
A14: AYAM KECAP | C14: Ayam Kecap (pack) | D14: pack | E14: 1000 | F14: gr | G14: YA | H14: YA | K14: COM DEVIASI - RESTO | L14: DEVIASI | M14: N/A | N14: N/A | O14: N/A | P14: N/A
A15: AYAM KECAP | C15: Ayam Kecap (gr) | D15: gr | E15: 1 | F15: gr | G15: YA | H15: YA | K15: COM DEVIASI - RESTO | L15: DEVIASI | M15: N/A | N15: N/A | O15: N/A | P15: N/A
A16: AYAM KECAP | B16: 100386 | C16: AYAM KECAP | D16: GR | G16: YA | H16: YA | K16: COM DEVIASI - RESTO | L16: DEVIASI | M16: N/A | N16: N/A | O16: N/A | P16: N/A
A17: BAKSO HALUS | C17: Bakso Halus (karton) | D17: karton | E17: 480 | F17: pcs | G17: YA | H17: YA | K17: COM DEVIASI - RESTO | L17: DEVIASI | M17: TRUE | N17: TRUE | O17: TRUE | P17: TRUE
A18: BAKSO HALUS | C18: Bakso Halus (pack) | D18: pack | E18: 40 | F18: pcs | G18: YA | H18: YA | K18: COM DEVIASI - RESTO | L18: DEVIASI | M18: TRUE | N18: TRUE | O18: TRUE | P18: TRUE
A19: BAKSO HALUS | C19: Bakso Halus (Pcs) | D19: pcs | E19: 1 | F19: pcs | G19: YA | H19: YA | K19: COM DEVIASI - RESTO | L19: DEVIASI | M19: TRUE | N19: TRUE | O19: TRUE | P19: TRUE
A20: BAKSO HALUS | B20: 100389 | C20: BAKSO HALUS | D20: PCS | G20: YA | H20: YA | K20: COM DEVIASI - RESTO | L20: DEVIASI | M20: TRUE | N20: TRUE | O20: TRUE | P20: TRUE
A21: BAKSO URAT | C21: Bakso Urat (karton) | D21: karton | E21: 480 | F21: pcs | G21: YA | H21: YA | K21: COM DEVIASI - RESTO | L21: DEVIASI | M21: TRUE | N21: TRUE | O21: TRUE | P21: TRUE
A22: BAKSO URAT | C22: Bakso Urat (pack) | D22: pack | E22: 40 | F22: pcs | G22: YA | H22: YA | K22: COM DEVIASI - RESTO | L22: DEVIASI | M22: TRUE | N22: TRUE | O22: TRUE | P22: TRUE
A23: BAKSO URAT | C23: Bakso Urat (pcs) | D23: pcs | E23: 1 | F23: pcs | G23: YA | H23: YA | K23: COM DEVIASI - RESTO | L23: DEVIASI | M23: TRUE | N23: TRUE | O23: TRUE | P23: TRUE
A24: BAKSO URAT | B24: 100388 | C24: BAKSO URAT | D24: PCS | G24: YA | H24: YA | K24: COM DEVIASI - RESTO | L24: DEVIASI | M24: TRUE | N24: TRUE | O24: TRUE | P24: TRUE
A25: BASIC POWDER | C25: Basic Powder (pack) | D25: pack | E25: 1000 | F25: gr | G25: YA | H25: YA | K25: COM DEVIASI - RESTO | L25: DEVIASI | M25: N/A | N25: N/A | O25: N/A | P25: N/A
A26: BASIC POWDER | C26: Basic Powder (gr) | D26: gr | E26: 1 | F26: gr | G26: YA | H26: YA | K26: COM DEVIASI - RESTO | L26: DEVIASI | M26: N/A | N26: N/A | O26: N/A | P26: N/A
A27: BASIC POWDER | B27: 100406 | C27: BASIC POWDER | D27: GR | G27: YA | H27: YA | K27: COM DEVIASI - RESTO | L27: DEVIASI | M27: N/A | N27: N/A | O27: N/A | P27: N/A
A28: BASRENG | C28: Basreng (karton) | D28: karton | E28: 150 | F28: pcs | G28: YA | H28: YA | K28: COM DEVIASI - RESTO | L28: DEVIASI | M28: TRUE | N28: TRUE | O28: TRUE | P28: TRUE
A29: BASRENG | C29: Basreng (pack) | D29: pack | E29: 15 | F29: pcs | G29: YA | H29: YA | K29: COM DEVIASI - RESTO | L29: DEVIASI | M29: TRUE | N29: TRUE | O29: TRUE | P29: TRUE
A30: BASRENG | C30: Basreng (pcs) | D30: pack | E30: 1 | F30: pcs | G30: YA | H30: YA | K30: COM DEVIASI - RESTO | L30: DEVIASI | M30: TRUE | N30: TRUE | O30: TRUE | P30: TRUE
A31: BASRENG | B31: 100390 | C31: BASRENG | D31: PCS | G31: YA | H31: YA | K31: COM DEVIASI - RESTO | L31: DEVIASI | M31: TRUE | N31: TRUE | O31: TRUE | P31: TRUE
A32: BAWANG MERAH GORENG | C32: Bawang Merah Goreng (karton) | D32: karton | E32: 7500 | F32: gr | G32: YA | H32: YA | K32: COM DEVIASI - RESTO | L32: DEVIASI | M32: TRUE | N32: TRUE | O32: TRUE | P32: TRUE
A33: BAWANG MERAH GORENG | C33: Bawang Merah Goreng (pack) | D33: pack | E33: 500 | F33: gr | G33: YA | H33: YA | K33: COM DEVIASI - RESTO | L33: DEVIASI | M33: TRUE | N33: TRUE | O33: TRUE | P33: TRUE
A34: BAWANG MERAH GORENG | C34: Bawang Merah Goreng (gr) | D34: gr | E34: 1 | F34: gr | G34: YA | H34: YA | K34: COM DEVIASI - RESTO | L34: DEVIASI | M34: TRUE | N34: TRUE | O34: TRUE | P34: TRUE
A35: BAWANG MERAH GORENG | C35: Bawang Merah Goreng dari Sambel Bakso (gr) | D35: gr | E35: =12/3453 -> 0.0034752389 | F35: gr | G35: YA | H35: TIDAK | I35: Kuah Bakso dari sambal bakso (gr) | J35: HIDE | K35: COM DEVIASI - RESTO | L35: DEVIASI | M35: TRUE | N35: TRUE | O35: TRUE | P35: TRUE
A36: BAWANG MERAH GORENG | C36: Bawang Merah Goreng dari Kuah Bakso (gr) | D36: gr | E36: =200/380664 -> 0.00052539773 | F36: gr | G36: TIDAK | H36: TIDAK | I36: Kuah Bakso (gr) | J36: HIDE | K36: COM DEVIASI - RESTO | L36: DEVIASI | M36: TRUE | N36: TRUE | O36: TRUE | P36: TRUE
A37: BAWANG MERAH GORENG | B37: 100340 | C37: BAWANG MERAH GORENG | D37: GR | G37: YA | H37: YA | K37: COM DEVIASI - RESTO | L37: DEVIASI | M37: TRUE | N37: TRUE | O37: TRUE | P37: TRUE
A38: BAWANG PUTIH GORENG (V.20) | C38: Bawang Putih Goreng (karton) | D38: karton | E38: 7500 | F38: gr | G38: YA | H38: YA | K38: COM DEVIASI - RESTO | L38: DEVIASI | M38: TRUE | N38: TRUE | O38: TRUE | P38: TRUE
A39: BAWANG PUTIH GORENG (V.20) | C39: Bawang Putih Goreng (pack) | D39: pack | E39: 500 | F39: gr | G39: YA | H39: YA | K39: COM DEVIASI - RESTO | L39: DEVIASI | M39: TRUE | N39: TRUE | O39: TRUE | P39: TRUE
A40: BAWANG PUTIH GORENG (V.20) | C40: Bawang Putih Goreng (gr) | D40: gr | E40: 1 | F40: gr | G40: YA | H40: YA | K40: COM DEVIASI - RESTO | L40: DEVIASI | M40: TRUE | N40: TRUE | O40: TRUE | P40: TRUE
...

Sheet DBS_BOM
A1: Nama Barang Grup Barang | B1: NAMA BARANG | C1: Kuantitas | D1: Satuan2
A2: BAKSO SUPER HALUS - DINE IN | B2: BAKSO HALUS | C2: 4 | D2: PCS
A3: BAKSO SUPER HALUS - DINE IN | B3: CABE RAWIT - RESTO (V.20) | C3: 3.3 | D3: GR
A4: BAKSO SUPER HALUS - DINE IN | B4: SOHUN | C4: 10 | D4: GR
A5: BAKSO SUPER HALUS - DINE IN | B5: DAUN BAWANG FRESH | C5: 1.25 | D5: GR
A6: BAKSO SUPER HALUS - DINE IN | B6: SAOS TOMAT | C6: 9 | D6: GR
A7: BAKSO SUPER HALUS - DINE IN | B7: KECAP BAKSO | C7: 9 | D7: GR
A8: BAKSO SUPER HALUS - DINE IN | B8: BAWANG MERAH GORENG | C8: 2.25 | D8: GR
A9: BAKSO SUPER HALUS - DINE IN | B9: BUMBU PASTA KUAH (V.20) | C9: 5.7 | D9: GR
A10: BAKSO SUPER HALUS - DINE IN | B10: BAWANG PUTIH GORENG (V.20) | C10: 0.6 | D10: GR
A11: BAKSO SUPER HALUS - DINE IN | B11: BIANG KERING KUAH | C11: 4.83 | D11: GR
A12: BAKSO SUPER HALUS - DINE IN | B12: TAHU BAKSO | C12: 1 | D12: PCS
A13: BAKSO SUPER HALUS - DINE IN | B13: ADONAN GORENG MEKAR | C13: 17 | D13: GR
... A220: GORENG MEKAR 1 PCS | B220: KULIT PANGSIT GORENG MEKAR | C220: 25 | D220: GR

Sheet DBS_TRIALdanSUSUT
A1: Helper | B1: NAMA BARANG | C1: KETERANGAN | D1: SATUAN | E1: KONVERSI | F1: LINK BARANG
B2: ADONAN GORENG MEKAR | D2: GR | E2: 1
A3: Hide | B3: ADONAN GORENG MEKAR | D3: GR | E3: 17 | F3: GORENG MEKAR
B4: AIR MINERAL BOTOL (V.20) | D4: BOTOL | E4: 1
B5: AYAM KECAP | D5: GR | E5: 1
B6: BAKSO HALUS | D6: PCS | E6: 1
B7: BAKSO URAT | D7: PCS | E7: 1
B8: BASIC POWDER | D8: GR | E8: 1
B9: BASRENG | D9: PCS | E9: 1
B10: BAWANG MERAH GORENG | D10: GR | E10: 1
A11: Hide | B11: BAWANG MERAH GORENG | D11: GR | E11: =200/380664 -> 0.00052539773 | F11: KUAH BAKSO
A12: Hide | B12: BAWANG MERAH GORENG | D12: GR | E12: =200/37402*0.5 -> 0.0026736538 | F12: Cabe Giling ada kuah bakso
B13: BAWANG PUTIH GORENG (V.20) | D13: GR | E13: 1
A14: Hide | B14: BAWANG PUTIH GORENG (V.20) | D14: GR | E14: =100/380664 -> 0.00026269886 | F14: KUAH BAKSO
A15: Hide | B15: BAWANG PUTIH GORENG (V.20) | D15: GR | E15: =100/37402*0.5 -> 0.0013368269 | F15: Cabe Giling ada kuah bakso
B16: BERAS PUTIH | C16: Sisa Nasi dalam Paper Wrap | D16: GR | E16: =70/150 -> 0.46666667
B17: BERAS PUTIH | C17: Sisa Nasi dalam Tray | D17: GR | E17: =70/150 -> 0.46666667
B18: BIANG KERING KUAH | D18: GR | E18: 1
A19: Hide | B19: BIANG KERING KUAH | D19: GR | E19: =810.4/380664 -> 0.0021289116 | F19: KUAH BAKSO
A20: Hide | B20: BIANG KERING KUAH | D20: GR | E20: =810.4/37402*0.5 -> 0.010833645 | F20: Cabe Giling ada kuah bakso
B21: BLUEBERRY SAUCE | D21: GR | E21: 1
B22: BUBBLEGUM CRUMBLE | D22: GR | E22: 1
B23: BUBBLEGUM SAUCE | D23: GR | E23: 1
B24: BUMBU BAKSO BAKAR (V.20) | D24: GR | E24: 1
B25: BUMBU BAKSO BAKAR (V.20) | C25: Sisa Bumbu Bakso Bakar Cabe Lv 2 (Gr) | D25: GR | E25: 1
B26: BUMBU BAKSO BAKAR (V.20) | C26: Sisa Bumbu Bakso Bakar Cabe Lv 4 (Gr) | D26: GR | E26: 1
B27: BUMBU BAKSO BAKAR (V.20) | C27: Sisa Bumbu Bakso Bakar Cabe Lv 6 (Gr) | D27: GR | E27: 1
B28: BUMBU PASTA KUAH (V.20) | D28: GR | E28: 1
A29: Hide | B29: BUMBU PASTA KUAH (V.20) | D29: GR | E29: =956/380664 -> 0.0025114011 | F29: KUAH BAKSO
A30: Hide | B30: BUMBU PASTA KUAH (V.20) | D30: GR | E30: =1292/37402*0.5 -> 0.017271804 | F30: Cabe Giling ada kuah bakso
B31: CABE RAWIT - RESTO (V.20) | D31: GR | E31: 1
B32: CABE RAWIT - RESTO (V.20) | C32: Cabe Giling ada kuah bakso | D32: GR | E32: 1
A33: Hide | B33: CABE RAWIT - RESTO (V.20) | D33: GR | E33: =2/100 -> 0.02 | F33: Sisa Bumbu Bakso Bakar Cabe Lv 2 (Gr)
A34: Hide | B34: CABE RAWIT - RESTO (V.20) | D34: GR | E34: =8/100 -> 0.08 | F34: Sisa Bumbu Bakso Bakar Cabe Lv 4 (Gr)
A35: Hide | B35: CABE RAWIT - RESTO (V.20) | D35: GR | E35: =20/100 -> 0.2 | F35: Sisa Bumbu Bakso Bakar Cabe Lv 6 (Gr)
B36: CARAMEL CRUMB | D36: GR | E36: 1
B37: CARAMEL SAUCE | D37: ML | E37: 1
B38: CHEESECAKE BISKUIT | D38: GR | E38: 1
B39: CUP 16 - BAKSO | D39: PCS | E39: 1
B40: CUP SEALER - BAKSO | D40: PCS | E40: 1
...

Sheet DBS_Waste_Bnp
A1: Helper | B1: NAMA BARANG | C1: KETERANGAN | D1: PENYEBAB TERJADINYA WASTE | E1: SATUAN | F1: LINK BARANG | G1: KONVERSI
B2: ADONAN GORENG MEKAR | C2: Over Stock | D2: ADONAN GORENG MEKAR Karena Over Stock | E2: GR | G2: 1
B3: ADONAN GORENG MEKAR | C3: Handling | D3: ADONAN GORENG MEKAR Karena Handling | E3: GR | G3: 1
B4: ADONAN GORENG MEKAR | C4: Kualitas Internal | D4: ADONAN GORENG MEKAR Karena Kualitas Internal | E4: GR | G4: 1
B5: ADONAN GORENG MEKAR | C5: Alat/ Mesin | D5: ADONAN GORENG MEKAR Karena Alat/ Mesin | E5: GR | G5: 1
A6: HIDE | B6: ADONAN GORENG MEKAR | C6: Over Stock | D6: ADONAN GORENG MEKAR Karena Over Stock dari Goreng Mekar | E6: GR | F6: GORENG MEKAR Karena Over Stock | G6: 17
A7: HIDE | B7: ADONAN GORENG MEKAR | C7: Handling | D7: ADONAN GORENG MEKAR Karena Handling dari Goreng Mekar | E7: GR | F7: GORENG MEKAR Karena Handling | G7: 17
A8: HIDE | B8: ADONAN GORENG MEKAR | C8: Kualitas Internal | D8: ADONAN GORENG MEKAR Karena Kualitas Internal dari Goreng Mekar | E8: GR | F8: GORENG MEKAR Karena Kualitas Internal | G8: 17
A9: HIDE | B9: ADONAN GORENG MEKAR | C9: Alat/ Mesin | D9: ADONAN GORENG MEKAR Karena Alat/ Mesin dari Goreng Mekar | E9: GR | F9: GORENG MEKAR Karena Alat/ Mesin | G9: 17
B10: AIR MINERAL BOTOL (V.20) | C10: Over Stock | D10: AIR MINERAL BOTOL (V.20) Karena Over Stock | E10: BOTOL | G10: 1
B11: AIR MINERAL BOTOL (V.20) | C11: Handling | D11: AIR MINERAL BOTOL (V.20) Karena Handling | E11: BOTOL | G11: 1
B12: AIR MINERAL BOTOL (V.20) | C12: Kualitas Eksternal | D12: AIR MINERAL BOTOL (V.20) Karena Kualitas Eksternal | E12: BOTOL | G12: 1
B13: AIR MINERAL BOTOL (V.20) | C13: Alat/ Mesin | D13: AIR MINERAL BOTOL (V.20) Karena Alat/ Mesin | E13: BOTOL | G13: 1
B14: AYAM KECAP | C14: Over Stock | D14: AYAM KECAP Karena Over Stock | E14: GR | G14: 1
B15: AYAM KECAP | C15: Handling | D15: AYAM KECAP Karena Handling | E15: GR | G15: 1
B16: AYAM KECAP | C16: Kualitas Internal | D16: AYAM KECAP Karena Kualitas Internal | E16: GR | G16: 1
B17: AYAM KECAP | C17: Alat/ Mesin | D17: AYAM KECAP Karena Alat/ Mesin | E17: GR | G17: 1
B18: BAKSO HALUS | C18: Over Stock | D18: BAKSO HALUS Karena Over Stock | E18: PCS | G18: 1
B19: BAKSO HALUS | C19: Handling | D19: BAKSO HALUS Karena Handling | E19: PCS | G19: 1
B20: BAKSO HALUS | C20: Kualitas Internal | D20: BAKSO HALUS Karena Kualitas Internal | E20: PCS | G20: 1
B21: BAKSO HALUS | C21: Alat/ Mesin | D21: BAKSO HALUS Karena Alat/ Mesin | E21: PCS | G21: 1
... B53: BAWANG MERAH GORENG | C53: Alat/ Mesin | D53: BAWANG MERAH GORENG Karena Alat/ Mesin | E53: GR | G53: 1
A54: HIDE | B54: BAWANG MERAH GORENG | C54: Over Stock | D54: BAWANG MERAH GORENG dari Kuah Bakso Karena Over Stock | E54: GR | F54: KUAH BAKSO Karena Over Stock | G54: =200/380664 -> 0.00052539773
A55: HIDE | B55: BAWANG MERAH GORENG | C55: Handling | D55: BAWANG MERAH GORENG dari Kuah Bakso Karena Handling | E55: GR | F55: KUAH BAKSO Karena Handling | G55: =200/380664 -> 0.00052539773
A56: HIDE | B56: BAWANG MERAH GORENG | C56: Kualitas Internal | D56: BAWANG MERAH GORENG dari Kuah Bakso Karena Kualitas Internal | E56: GR | F56: KUAH BAKSO Karena Kualitas Internal | G56: =200/380664 -> 0.00052539773
A57: HIDE | B57: BAWANG MERAH GORENG | C57: Alat/ Mesin | D57: BAWANG MERAH GORENG dari Kuah Bakso Karena Alat/ Mesin | E57: GR | F57: KUAH BAKSO Karena Alat/ Mesin | G57: =200/380664 -> 0.00052539773
A58: HIDE | B58: BAWANG MERAH GORENG | C58: Over Stock | D58: BAWANG MERAH GORENG dari Sisa Cabe Kuah Bakso Karena Over Stock | E58: GR | F58: CABE RAWIT - RESTO Sisa Giling ada Kuah Bakso Karena Over Stock | G58: =200/37402*0.5 -> 0.0026736538
A59: HIDE | B59: BAWANG MERAH GORENG | C59: Handling | D59: BAWANG MERAH GORENG dari Sisa Cabe Kuah Bakso Karena Handling | E59: GR | F59: CABE RAWIT - RESTO Sisa Giling ada Kuah Bakso Karena Handling | G59: =200/37402*0.5 -> 0.0026736538
A60: HIDE | B60: BAWANG MERAH GORENG | C60: Kualitas Internal | D60: BAWANG MERAH GORENG dari Sisa Cabe Kuah Bakso Karena Kualitas Internal | E60: GR | F60: CABE RAWIT - RESTO Sisa Giling ada Kuah Bakso Karena Kualitas Eksternal | G60: =200/37402*0.5 -> 0.0026736538
A61: HIDE | B61: BAWANG MERAH GORENG | C61: Alat/ Mesin | D61: BAWANG MERAH GORENG dari Sisa Cabe Kuah Bakso Karena Alat/ Mesin | E61: GR | F61: CABE RAWIT - RESTO Sisa Giling ada Kuah Bakso Karena Alat/ Mesin | G61: =200/37402*0.5 -> 0.0026736538
B62: BAWANG PUTIH GORENG (V.20) | C62: Over Stock | D62: BAWANG PUTIH GORENG Karena Over Stock | E62: GR | G62: 1
B63: BAWANG PUTIH GORENG (V.20) | C63: Handling | D63: BAWANG PUTIH GORENG Karena Handling | E63: GR | G63: 1
B64: BAWANG PUTIH GORENG (V.20) | C64: Kualitas Internal | D64: BAWANG PUTIH GORENG Karena Kualitas Internal | E64: GR | G64: 1
B65: BAWANG PUTIH GORENG (V.20) | C65: Alat/ Mesin | D65: BAWANG PUTIH GORENG Karena Alat/ Mesin | E65: GR | G65: 1
A66: HIDE | B66: BAWANG PUTIH GORENG (V.20) | C66: Over Stock | D66: BAWANG PUTIH GORENG dari Kuah Bakso Karena Over Stock | E66: GR | F66: KUAH BAKSO Karena Over Stock | G66: =100/380664 -> 0.00026269886
A67: HIDE | B67: BAWANG PUTIH GORENG (V.20) | C67: Handling | D67: BAWANG PUTIH GORENG dari Kuah Bakso Karena Handling | E67: GR | F67: KUAH BAKSO Karena Handling | G67: =100/380664 -> 0.00026269886
A68: HIDE | B68: BAWANG PUTIH GORENG (V.20) | C68: Kualitas Internal | D68: BAWANG PUTIH GORENG dari Kuah Bakso Karena Kualitas Internal | E68: GR | F68: KUAH BAKSO Karena Kualitas Internal | G68: =100/380664 -> 0.00026269886
A69: HIDE | B69: BAWANG PUTIH GORENG (V.20) | C69: Alat/ Mesin | D69: BAWANG PUTIH GORENG dari Kuah Bakso Karena Alat/ Mesin | E69: GR | F69: KUAH BAKSO Karena Alat/ Mesin | G69: =100/380664 -> 0.00026269886
A70: HIDE | B70: BAWANG PUTIH GORENG (V.20) | C70: Over Stock | D70: BAWANG PUTIH GORENG dari Sisa Cabe Kuah Bakso Karena Over Stock | E70: GR | F70: CABE RAWIT - RESTO Sisa Giling ada Kuah Bakso Karena Over Stock | G70: =100/37402*0.5 -> 0.0013368269
A71: HIDE | B71: BAWANG PUTIH GORENG (V.20) | C71: Handling | D71: BAWANG PUTIH GORENG dari Sisa Cabe Kuah Bakso Karena Handling | E71: GR | F71: CABE RAWIT - RESTO Sisa Giling ada Kuah Bakso Karena Handling | G71: =100/37402*0.5 -> 0.0013368269
...

Sheet Detail1
A1: Details for Sum of Value - SATUAN: GR, JENIS: 1.DEVIASI, NAMA BARANG: KECAP BAKSO, KATEGORI: COM DEVIASI - RESTO, Attribute: 14
A3: KATEGORI | B3: NAMA BARANG | C3: JENIS | D3: SATUAN | E3: Attribute | F3: SO_KEMARIN | G3: WASTE | H3: TRIAL | I3: SUSUT | J3: STOCK AWAL | K3: BARANG MASUK | L3: BARANG KELUAR | M3: BOM | N3: Stock Seharusnya (SO_Kemarin + Barang Masuk - Barang Keluar - BOM) | O3: SO | P3: Value | Q3: Keterangan | R3: Indikasi
A4: COM DEVIASI - RESTO | B4: KECAP BAKSO | C4: 1.DEVIASI | D4: GR | E4: 14 | F4: 65754 | G4: 0 | H4: 72 | I4: 0 | K4: 12000 | L4: 0 | M4: 13752 | N4: 64002 | O4: 52950 | P4: -11052 | Q4: SO lebih sedikit daripada perhitungan stock seharusnya | R4: 1. Barang Keluar belum tercatat (Kiriman/retur ke resto lain/DC) | 2. Pencatatan Promix 00 kurang tepat | 3. Loss karna Waste/Susut atau Over Takaran

Sheet AKUMULASI DEVIASI ATAU TOTAL

Sheet CEK DEVIASI HARIAN

Sheet INPUT SO HARIAN
A1: NAMA BARANG | B1: KODE BARANG | C1: ITEM STOCK OPNAME | D1: SATUAN | E1: Konversi | F1: 1 | G1: 2 | H1: 3 | I1: 4 | J1: 5 | K1: 6 | L1: 7 | M1: 8 | N1: 9 | O1: 10 | P1: 11 | Q1: 12 | R1: 13 | S1: 14 | T1: 15 | U1: 16 | V1: 17 | W1: 18 | X1: 19 | Y1: 20 | Z1: 21 | AA1: 22 | AB1: 23 | AC1: 24 | AD1: 25 | AE1: 26 | AF1: 27 | AG1: 28 | AH1: 29 | AI1: 30 | AJ1: 31
A2: ADONAN GORENG MEKAR | C2: Adonan Goreng Mekar (karton) | D2: karton | E2: 15000 | F2: 0 | G2: 0 | H2: 1 | I2: 0 | J2: 7 | K2: 0 | L2: 6 | M2: 5 | N2: 10 | O2: 9 | P2: 5 | Q2: 7 | R2: 3 | S2: 10
A3: ADONAN GORENG MEKAR | C3: Adonan Goreng Mekar (pack) | D3: pack | E3: 1000 | F3: 131 | G3: 92 | H3: 109 | I3: 109 | J3: 116 | K3: =144+69 -> 213 | L3: =70+19+69 -> 158 | M3: =135+69 -> 204 | N3: =79+69 -> 148 | O3: 71 | P3: 57 | Q3: 93 | R3: 87 | S3: 74
A4: ADONAN GORENG MEKAR | C4: Adonan Goreng Mekar (gr) | D4: gr | E4: 1 | F4: 439 | G4: 0 | H4: 0 | I4: 0 | J4: 0 | K4: 612 | L4: 0 | M4: 0 | N4: 0 | O4: 708 | P4: 662 | Q4: 0 | R4: 0 | S4: 0
A5: ADONAN GORENG MEKAR | B5: 100434 | C5: ADONAN GORENG MEKAR | D5: GR
A6: AIR MINERAL BOTOL (V.20) | C6: stok air mineral kardus utuh (karton) | D6: karton | E6: 24 | F6: 33 | G6: 73 | H6: 56 | I6: 41 | J6: 29 | K6: 53 | L6: 39 | M6: 25 | N6: 76 | O6: 60 | P6: 44 | Q6: 21 | R6: 61 | S6: 47
A7: AIR MINERAL BOTOL (V.20) | C7: sisa air mineral botol (botol) | D7: botol | E7: 1 | F7: 10 | G7: 7 | H7: 15 | I7: 22 | J7: 17 | K7: 9 | L7: 20 | M7: 34 | N7: 13 | O7: 31 | P7: 19 | Q7: 34 | R7: 1 | S7: 37
A8: AIR MINERAL BOTOL (V.20) | B8: 100210 | C8: AIR MINERAL BOTOL (V.20) | D8: BOTOL
A9: ARANG BAKARAN | C9: Arang Bakaran (karton) | D9: karton | E9: 10000 | F9: 0 | G9: 0 | H9: 0 | I9: 0 | J9: 0 | K9: 0 | L9: 0 | M9: 0 | N9: 0 | O9: 0 | P9: 0 | Q9: 0 | R9: 0 | S9: 0
A10: ARANG BAKARAN | C10: Arang Bakaran (gr) | D10: gr | E10: 1 | F10: 553860 | G10: 526460 | H10: 496270 | I10: 465440 | J10: 435457 | K10: 395933 | L10: 371602 | M10: 344455 | N10: 311391 | O10: 279660 | P10: 250145 | Q10: 226499 | R10: 20353 | S10: 153000
A11: ARANG BAKARAN | B11: 100351 | C11: ARANG BAKARAN | D11: GR
A12: AYAM KECAP | C12: Ayam Kecap (karton) | D12: karton | E12: 12000
A13: AYAM KECAP | C13: Ayam Kecap (pack) | D13: pack | E13: 1000
A14: AYAM KECAP | C14: Ayam Kecap (gr) | D14: gr | E14: 1
A15: AYAM KECAP | B15: 100386 | C15: AYAM KECAP | D15: GR
A16: BAKSO HALUS | C16: Bakso Halus (karton) | D16: karton | E16: 480 | F16: 41 | G16: 22 | H16: 42 | I16: 25 | J16: 48 | K16: 33 | L16: 53 | M16: 41 | N16: 39 | O16: 57 | P16: 38 | Q16: 52 | R16: 37 | S16: 46
A17: BAKSO HALUS | C17: Bakso Halus (pack) | D17: pack | E17: 40 | F17: 24 | G17: 116 | H17: 48 | I17: 0 | J17: 36 | K17: 6 | L17: 11 | M17: 0 | N17: 26 | O17: 34 | P17: 26 | Q17: 48 | R17: 38 | S17: 8
A18: BAKSO HALUS | C18: Bakso Halus (Pcs) | D18: pcs | E18: 1 | F18: 1918 | G18: 1936 | H18: 0.00 | I18: 0.00 | J18: 64.00 | K18: 39 | L18: 154.00 | M18: 44.00 | N18: 105 | O18: 70 | P18: 79 | Q18: 123 | R18: 90 | S18: 35
A19: BAKSO HALUS | B19: 100389 | C19: BAKSO HALUS | D19: PCS
A20: BAKSO URAT | C20: Bakso Urat (karton) | D20: karton | E20: 480 | F20: 31 | G20: 19 | H20: 25 | I20: 15 | J20: 29 | K20: 21 | L20: 39 | M20: 31 | N20: 26 | O20: 36 | P20: 24 | Q20: 34 | R20: 24 | S20: 31
A21: BAKSO URAT | C21: Bakso Urat (pack) | D21: pack | E21: 40 | F21: 32 | G21: 77 | H21: 36 | I21: 0 | J21: 54 | K21: 1 | L21: 9 | M21: 3 | N21: 22 | O21: 34 | P21: 32 | Q21: 52 | R21: 50 | S21: 10
A22: BAKSO URAT | C22: Bakso Urat (pcs) | D22: pcs | E22: 1 | F22: 958 | G22: 1040 | H22: 0 | I22: 0 | J22: 6 | K22: 8 | L22: 88 | M22: 87 | N22: 97 | O22: 36 | P22: 66 | Q22: 28 | R22: 58 | S22: 26
A23: BAKSO URAT | B23: 100388 | C23: BAKSO URAT | D23: PCS
A24: BASIC POWDER | C24: Basic Powder (pack) | D24: pack | E24: 1000
A25: BASIC POWDER | C25: Basic Powder (gr) | D25: gr | E25: 1
A26: BASIC POWDER | B26: 100406 | C26: BASIC POWDER | D26: GR
A27: BASRENG | C27: Basreng (karton) | D27: karton | E27: 150 | F27: 36 | G27: 15 | H27: =43+2 -> 45 | I27: 14 | J27: 34 | K27: 20 | L27: 31 | M27: 62 | N27: 63 | O27: 1 | P27: 0 | Q27: 10 | R27: 2 | S27: 10
A28: BASRENG | C28: Basreng (pack) | D28: pack | E28: 15 | F28: 283 | G28: 325 | H28: =196+18 -> 214 | I28: 265 | J28: 263 | K28: =266+654 -> 920 | L28: =221+654 -> 875 | M28: =260+654 -> 914 | N28: =301+654 -> 955 | O28: =217+15 -> 232 | P28: 20 | Q28: 237 | R28: 209 | S28: 229
A29: BASRENG | C29: Basreng (pcs) | D29: pack | E29: 1 | F29: 24 | G29: 22 | H29: 9 | I29: 0 | J29: 2 | K29: 9 | L29: 0 | M29: 0 | N29: 0 | O29: 35 | P29: 1 | Q29: 6 | R29: 12 | S29: 12
A30: BASRENG | B30: 100390 | C30: BASRENG | D30: PCS
A31: BAWANG MERAH GORENG | C31: Bawang Merah Goreng (karton) | D31: karton | E31: 7500 | F31: 3 | G31: 3 | H31: 5 | I31: 3 | J31: 3 | K31: 2 | L31: 4 | M31: 3 | N31: 2 | O31: 5 | P31: 4 | Q31: 3 | R31: 3 | S31: 4
A32: BAWANG MERAH GORENG | C32: Bawang Merah Goreng (pack) | D32: pack | E32: 500 | F32: 11 | G32: 2 | H32: 2 | I32: 11 | J32: 4 | K32: 6 | L32: 7 | M32: 10 | N32: 11 | O32: 10 | P32: 9 | Q32: 12 | R32: 4 | S32: 8
A33: BAWANG MERAH GORENG | C33: Bawang Merah Goreng (gr) | D33: gr | E33: 1 | F33: 600 | G33: 0 | H33: 0 | I33: 317 | J33: 182 | K33: 401 | L33: 341 | M33: 587 | N33: 0 | O33: 553 | P33: 314 | Q33: 441 | R33: 649 | S33: 61
A34: BAWANG MERAH GORENG | B34: 100340 | C34: BAWANG MERAH GORENG | D34: GR
A35: BAWANG PUTIH GORENG (V.20) | C35: Bawang Putih Goreng (karton) | D35: karton | E35: 7500 | F35: 1 | G35: 1 | H35: 2 | I35: 1 | J35: 1 | K35: 1 | L35: 1 | M35: 1 | N35: 1 | O35: 2 | P35: 1 | Q35: 2 | R35: 2 | S35: 2
A36: BAWANG PUTIH GORENG (V.20) | C36: Bawang Putih Goreng (pack) | D36: pack | E36: 500 | F36: 19 | G36: 16 | H36: 8 | I36: 13 | J36: 22 | K36: 20 | L36: 16 | M36: 14 | N36: 11 | O36: 8 | P36: 19 | Q36: 17 | R36: 15 | S36: 12
A37: BAWANG PUTIH GORENG (V.20) | C37: Bawang Putih Goreng (gr) | D37: gr | E37: 1 | F37: 500 | G37: 0 | H37: 0 | I37: 406 | J37: 518 | K37: 316 | L37: 401 | M37: 113 | N37: 203 | O37: 96 | P37: 276 | Q37: 285 | R37: 96 | S37: 515
A38: BAWANG PUTIH GORENG (V.20) | B38: 100430 | C38: BAWANG PUTIH GORENG (V.20) | D38: GR
A39: BERAS PUTIH | C39: Beras Putih (Karung) | D39: karung | E39: 25000 | F39: 1 | G39: 1 | H39: 1 | I39: 1 | J39: 1 | K39: 1 | L39: 1 | M39: 1 | N39: 1 | O39: 1 | P39: 1 | Q39: 1 | R39: 1 | S39: 1
A40: BERAS PUTIH | C40: Beras Putih (gr) | D40: gr | E40: 1 | F40: 19070 | G40: 19070 | H40: 19070 | I40: 19070 | J40: 9800 | K40: 9800 | L40: 9800 | M40: 9800 | N40: 9800 | O40: 9800 | P40: 9800 | Q40: 9800 | R40: 18700 | S40: 19250
...

Sheet INPUT BARANG MASUK
A1: NAMA BARANG | B1: KODE BARANG | C1: ITEM STOCK OPNAME | D1: SATUAN | E1: Konversi | F1: 1 | G1: 2 | H1: 3 | I1: 4 | J1: 5 | K1: 6 | L1: 7 | M1: 8 | N1: 9 | O1: 10 | P1: 11 | Q1: 12 | R1: 13 | S1: 14 | T1: 15 | U1: 16 | V1: 17 | W1: 18 | X1: 19 | Y1: 20 | Z1: 21 | AA1: 22 | AB1: 23 | AC1: 24 | AD1: 25 | AE1: 26 | AF1: 27 | AG1: 28 | AH1: 29 | AI1: 30 | AJ1: 31
A2: ADONAN GORENG MEKAR | C2: Adonan Goreng Mekar (karton) | D2: karton | E2: 15000 | J2: 9 | L2: 7 | M2: 3 | N2: =4 -> 4 | Q2: =7 -> 7 | S2: 4
A3: ADONAN GORENG MEKAR | C3: Adonan Goreng Mekar (pack) | D3: pack | E3: 1000 | H3: 13
A4: ADONAN GORENG MEKAR | C4: Adonan Goreng Mekar (gr) | D4: gr | E4: 1 | O4: 50000 | AL4: =13000 -> 13000
A5: ADONAN GORENG MEKAR | B5: 100434 | C5: ADONAN GORENG MEKAR | D5: GR
A6: AIR MINERAL BOTOL (V.20) | C6: stok air mineral kardus utuh (karton) | D6: karton | E6: 24 | G6: 55 | K6: =35 -> 35 | N6: =60 -> 60 | R6: 40
A7: AIR MINERAL BOTOL (V.20) | C7: sisa air mineral botol (botol) | D7: botol | E7: 1
A8: AIR MINERAL BOTOL (V.20) | B8: 100210 | C8: AIR MINERAL BOTOL (V.20) | D8: BOTOL
A9: ARANG BAKARAN | C9: Arang Bakaran (karton) | D9: karton | E9: 10000 | J9: 2
A10: ARANG BAKARAN | C10: Arang Bakaran (gr) | D10: gr | E10: 1
A11: ARANG BAKARAN | B11: 100351 | C11: ARANG BAKARAN | D11: GR
A12: AYAM KECAP | C12: Ayam Kecap (karton) | D12: karton | E12: 12000
A13: AYAM KECAP | C13: Ayam Kecap (pack) | D13: pack | E13: 1000
A14: AYAM KECAP | C14: Ayam Kecap (gr) | D14: gr | E14: 1
A15: AYAM KECAP | B15: 100386 | C15: AYAM KECAP | D15: GR
A16: BAKSO HALUS | C16: Bakso Halus (karton) | D16: karton | E16: 480 | J16: 35 | L16: 34 | N16: =192/12 -> 16 | Q16: =26 -> 26 | S16: 16
A17: BAKSO HALUS | C17: Bakso Halus (pack) | D17: pack | E17: 40 | H17: =456 -> 456 | O17: 432
A18: BAKSO HALUS | C18: Bakso Halus (Pcs) | D18: pcs | E18: 1
A19: BAKSO HALUS | B19: 100389 | C19: BAKSO HALUS | D19: PCS
A20: BAKSO URAT | C20: Bakso Urat (karton) | D20: karton | E20: 480 | F20: =40 -> 40 | J20: 21 | L20: 28 | N20: =72/12 -> 6 | Q20: =18 -> 18 | S20: 6
A21: BAKSO URAT | C21: Bakso Urat (pack) | D21: pack | E21: 40 | H21: =192 -> 192 | O21: 264
A22: BAKSO URAT | C22: Bakso Urat (pcs) | D22: pcs | E22: 1
A23: BAKSO URAT | B23: 100388 | C23: BAKSO URAT | D23: PCS
A24: BASIC POWDER | C24: Basic Powder (pack) | D24: pack | E24: 1000
A25: BASIC POWDER | C25: Basic Powder (gr) | D25: gr | E25: 1
A26: BASIC POWDER | B26: 100406 | C26: BASIC POWDER | D26: GR
A27: BASRENG | C27: Basreng (karton) | D27: karton | E27: 150 | J27: 32 | L27: 19 | M27: 46 | N27: =190/10 -> 19 | Q27: =22 -> 22 | S27: 19
A28: BASRENG | C28: Basreng (pack) | D28: pack | E28: 15 | H28: =350 -> 350 | O28: 190 | Q28: =168 -> 168
A29: BASRENG | C29: Basreng (pcs) | D29: pack | E29: 1
A30: BASRENG | B30: 100390 | C30: BASRENG | D30: PCS
A31: BAWANG MERAH GORENG | C31: Bawang Merah Goreng (karton) | D31: karton | E31: 7500 | H31: =3 -> 3
A32: BAWANG MERAH GORENG | C32: Bawang Merah Goreng (pack) | D32: pack | E32: 500
A33: BAWANG MERAH GORENG | C33: Bawang Merah Goreng (gr) | D33: gr | E33: 1 | L33: 15000 | O33: 20000 | S33: 10000
A34: BAWANG MERAH GORENG | B34: 100340 | C34: BAWANG MERAH GORENG | D34: GR
A35: BAWANG PUTIH GORENG (V.20) | C35: Bawang Putih Goreng (karton) | D35: karton | E35: 7500 | H35: =1 -> 1 | Q35: =1 -> 1
A36: BAWANG PUTIH GORENG (V.20) | C36: Bawang Putih Goreng (pack) | D36: pack | E36: 500
A37: BAWANG PUTIH GORENG (V.20) | C37: Bawang Putih Goreng (gr) | D37: gr | E37: 1 | O37: 7500
A38: BAWANG PUTIH GORENG (V.20) | B38: 100430 | C38: BAWANG PUTIH GORENG (V.20) | D38: GR
A39: BERAS PUTIH | C39: Beras Putih (Karung) | D39: karung | E39: 25000
A40: BERAS PUTIH | C40: Beras Putih (gr) | D40: gr | E40: 1
...

Sheet INPUT PENJUALAN 00
A1: Menu | B1: 1 | C1: 2 | D1: 3 | E1: 4 | F1: 5 | G1: 6 | H1: 7 | I1: 8 | J1: 9 | K1: 10 | L1: 11 | M1: 12 | N1: 13 | O1: 14 | P1: 15 | Q1: 16 | R1: 17 | S1: 18 | T1: 19 | U1: 20 | V1: 21 | W1: 22 | X1: 23 | Y1: 24 | Z1: 25 | AA1: 26 | AB1: 27 | AC1: 28 | AD1: 29 | AE1: 30 | AF1: 31
A2: |BAKSO BAKAR - DINE IN|
A3: BAKSO BAKAR LV 0 - DINE IN | B3: 147 | C3: 132 | D3: 169 | E3: 182 | F3: 111 | G3: 113 | H3: 98 | I3: 91 | J3: 135 | K3: 151 | L3: 187 | M3: 93 | N3: 105 | O3: 94
A4: BAKSO BAKAR LV 2 - DINE IN | B4: 279 | C4: 299 | D4: 342 | E4: 392 | F4: 288 | G4: 259 | H4: 269 | I4: 252 | J4: 286 | K4: 349 | L4: 352 | M4: 264 | N4: 242 | O4: 221
A5: BAKSO BAKAR LV 4 - DINE IN | B5: 88 | C5: 98 | D5: 90 | E5: 95 | F5: 90 | G5: 83 | H5: 72 | I5: 69 | J5: 73 | K5: 106 | L5: 97 | M5: 52 | N5: 60 | O5: 69
A6: BAKSO BAKAR LV 6 - DINE IN
A8: |BAKSO - DINE IN|
A9: BAKSO SUPER HALUS - DINE IN | B9: 411 | C9: 501 | D9: 567 | E9: 586 | F9: 388 | G9: 368 | H9: 383 | I9: 363 | J9: 405 | K9: 524 | L9: 627 | M9: 398 | N9: 377 | O9: 371
A10: BAKSO SUPER URAT - DINE IN | B10: 507 | C10: 507 | D10: 525 | E10: 594 | F10: 477 | G10: 454 | H10: 466 | I10: 463 | J10: 470 | K10: 627 | L10: 628 | M10: 452 | N10: 409 | O10: 425
A11: BAKSO SUPER CAMPUR - DINE IN | B11: 985 | C11: 1010 | D11: 1142 | E11: 1071 | F11: 909 | G11: 852 | H11: 934 | I11: 825 | J11: 926 | K11: 1091 | L11: 1233 | M11: 741 | N11: 806 | O11: 732
A13: |BAKSO GORENG - DINE IN|
A14: BASRENG - DINE IN | B14: 620 | C14: 615 | D14: 713 | E14: 741 | F14: 505 | G14: 527 | H14: 523 | I14: 476 | J14: 513 | K14: 675 | L14: 779 | M14: 477 | N14: 430 | O14: 455
A16: |BEVERAGES NESTLE - DINE IN|
A17: LEMON TEA ICE - DINE IN - RESTO BAKSO | B17: 329 | C17: 316 | D17: 338 | E17: 368 | F17: 312 | G17: 271 | H17: 349 | I17: 264 | J17: 326 | K17: 376 | L17: 388 | M17: 277 | N17: 287 | O17: 264
A18: ORANGE ICE - DINE IN - RESTO BAKSO | B18: 339 | C18: 385 | D18: 373 | E18: 435 | F18: 307 | G18: 362 | H18: 290 | I18: 296 | J18: 314 | K18: 498 | L18: 505 | M18: 253 | N18: 306 | O18: 291
A19: TEA ICE - DINE IN - RESTO BAKSO | B19: 496 | C19: 501 | D19: 616 | E19: 611 | F19: 481 | G19: 427 | H19: 421 | I19: 400 | J19: 481 | K19: 567 | L19: 691 | M19: 429 | N19: 391 | O19: 412
A21: |BAKSO BAKAR - TAKE AWAY|
A22: BAKSO BAKAR LV 0 - TAKE AWAY | B22: 40 | C22: 32 | D22: 26 | E22: 31 | F22: 6 | G22: 31 | H22: 14 | I22: 13 | J22: 31 | K22: 28 | L22: 23 | M22: 16 | N22: 22 | O22: 22
A23: BAKSO BAKAR LV 2 - TAKE AWAY | B23: 78 | C23: 40 | D23: 62 | E23: 49 | F23: 30 | G23: 45 | H23: 31 | I23: 39 | J23: 82 | K23: 45 | L23: 42 | M23: 30 | N23: 45 | O23: 32
A24: BAKSO BAKAR LV 4 - TAKE AWAY | B24: 17 | C24: 12 | D24: 14 | E24: 19 | F24: 12 | G24: 16 | H24: 9 | I24: 12 | J24: 11 | K24: 9 | L24: 12 | M24: 15 | N24: 12 | O24: 11
A25: BAKSO BAKAR LV 6 - TAKE AWAY
A27: |BAKSO - TAKE AWAY|
A28: BAKSO SUPER HALUS - TAKE AWAY | B28: 92 | C28: 69 | D28: 56 | E28: 85 | F28: 44 | G28: 90 | H28: 30 | I28: 74 | J28: 81 | K28: 70 | L28: 44 | M28: 59 | N28: 48 | O28: 73
A29: BAKSO SUPER URAT - TAKE AWAY | B29: 85 | C29: 65 | D29: 65 | E29: 67 | F29: 48 | G29: 53 | H29: 34 | I29: 55 | J29: 58 | K29: 66 | L29: 67 | M29: 44 | N29: 36 | O29: 61
A30: BAKSO SUPER CAMPUR - TAKE AWAY | B30: 212 | C30: 193 | D30: 292 | E30: 246 | F30: 129 | G30: 226 | H30: 171 | I30: 123 | J30: 248 | K30: 199 | L30: 199 | M30: 243 | N30: 156 | O30: 170
A32: |BAKSO GORENG - TAKE AWAY|
A33: BASRENG - TAKE AWAY | B33: 169 | C33: 123 | D33: 136 | E33: 140 | F33: 85 | G33: 143 | H33: 87 | I33: 91 | J33: 166 | K33: 95 | L33: 121 | M33: 85 | N33: 109 | O33: 120
A35: |BEVERAGES NESTLE - TAKE AWAY|
A36: LEMON TEA ICE - TAKE AWAY - RESTO BAKSO | B36: 9 | C36: 4 | D36: 8 | E36: 8 | F36: 6 | G36: 12 | H36: 2 | I36: 4 | J36: 10 | K36: 7 | L36: 8 | M36: 10 | N36: 8 | O36: 4
A37: ORANGE ICE - TAKE AWAY - RESTO BAKSO | B37: 9 | C37: 12 | D37: 9 | E37: 13 | F37: 5 | G37: 4 | H37: 5 | I37: 2 | J37: 6 | K37: 6 | L37: 7 | M37: 5 | N37: 9 | O37: 9
A38: TEA ICE - TAKE AWAY - RESTO BAKSO | B38: 11 | C38: 6 | D38: 14 | E38: 11 | F38: 14 | G38: 18 | H38: 9 | I38: 14 | J38: 11 | K38: 12 | L38: 16 | M38: 13 | N38: 20 | O38: 5
A40: |BEVERAGES - DINE IN/TAKE AWAY|
A41: AIR MINERAL BOTOL | B41: 348 | C41: 357 | D41: 393 | E41: 350 | F41: 293 | G41: 265 | H41: 297 | I41: 296 | J41: 284 | K41: 361 | L41: 393 | M41: 269 | N41: 270 | O41: 249
A42: COOKIES & CREAM SUNDAE - RESTO BAKSO | B42: 131 | C42: 140 | D42: 146 | E42: 172 | F42: 97 | G42: 108 | H42: 95 | I42: 103 | J42: 106 | K42: 131 | L42: 146 | M42: 92 | N42: 95 | O42: 81
A43: HAZELNUT CHOCO SUNDAE - RESTO BAKSO | B43: 140 | C43: 85 | D43: 99 | E43: 96 | F43: 69 | G43: 83 | H43: 70 | I43: 74 | J43: 52 | K43: 103 | L43: 99 | M43: 67 | N43: 58 | O43: 61
A44: MANGO KELLOGGS SUNDAE - RESTO BAKSO | B44: 70 | C44: 81 | D44: 78 | E44: 80 | F44: 62 | G44: 75 | H44: 61 | I44: 67 | J44: 41 | K44: 79 | L44: 85 | M44: 57 | N44: 47 | O44: 56
A45: VANILLA SUNDAE - RESTO BAKSO | B45: 53 | C45: 60 | D45: 70 | E45: 68 | F45: 49 | G45: 61 | H45: 48 | I45: 63 | J45: 49 | K45: 54 | L45: 74 | M45: 53 | N45: 39 | O45: 79
A46: BUBBLEGUM SUNDAE - RESTO BAKSO | B46: 97 | C46: 115 | D46: 136 | E46: 120 | F46: 85 | G46: 74 | H46: 91 | I46: 67 | J46: 68 | K46: 83 | L46: 119 | M46: 84 | N46: 83 | O46: 59
A47: BLUEBERRY CHEESECAKE SUNDAE - RESTO BAKSO | B47: 145 | C47: 117 | D47: 136 | E47: 134 | F47: 91 | G47: 104 | H47: 123 | I47: 97 | J47: 89 | K47: 116 | L47: 124 | M47: 109 | N47: 87 | O47: 88
A48: PISTACHIO KUNAFA SUNDAE - RESTO BAKSO | B48: 268 | C48: 266 | D48: 296 | E48: 319 | F48: 191 | G48: 200 | H48: 189 | I48: 201 | J48: 161 | K48: 232 | L48: 271 | M48: 205 | N48: 178 | O48: 162
...

Sheet REKAP MENTAH
A1: KATEGORI | B1: SOURCE DATA | C1: JENIS | D1: STATUS | E1: NAMA BARANG | F1: KETERANGAN | G1: PENYEBAB TERJADINYA WASTE | H1: SATUAN | I1: 1 | J1: 2 | K1: 3 | L1: 4 | M1: 5 | N1: 6 | O1: 7 | P1: 8 | Q1: 9 | R1: 10 | S1: 11 | T1: 12 | U1: 13 | V1: 14 | W1: 15 | X1: 16 | Y1: 17 | Z1: 18 | AA1: 19 | AB1: 20 | AC1: 21 | AD1: 22 | AE1: 23 | AF1: 24 | AG1: 25 | AH1: 26 | AI1: 27 | AJ1: 28 | AK1: 29 | AL1: 30 | AM1: 31
A2: BEBAN GAS - RESTO | B2: INPUT BARANG KELUAR | C2: BARANG KELUAR | D2: USAGE | E2: LPG 12KG | F2: BARANG KELUAR | H2: TABUNG | I2: 0 | J2: 0 | K2: 0 | L2: 0 | M2: 0 | N2: 0 | O2: 0 | P2: 0 | Q2: 0 | R2: 0 | S2: 0 | T2: 0 | U2: 0 | V2: 0 | W2: 0 | X2: 0 | Y2: 0 | Z2: 0 | AA2: 0 | AB2: 0 | AC2: 0 | AD2: 0 | AE2: 0 | AF2: 0 | AG2: 0 | AH2: 0 | AI2: 0 | AJ2: 0 | AK2: 0 | AL2: 0 | AM2: 0
A3: BEBAN GAS - RESTO | B3: INPUT BARANG MASUK | C3: BARANG MASUK | D3: USAGE | E3: LPG 12KG | F3: BARANG MASUK | H3: TABUNG | I3: 0 | J3: 0 | K3: 0 | L3: 0 | M3: 0 | N3: 0 | O3: 0 | P3: 0 | Q3: 0 | R3: 0 | S3: 0 | T3: 0 | U3: 0 | V3: 0 | W3: 0 | X3: 0 | Y3: 0 | Z3: 0 | AA3: 0 | AB3: 0 | AC3: 0 | AD3: 0 | AE3: 0 | AF3: 0 | AG3: 0 | AH3: 0 | AI3: 0 | AJ3: 0 | AK3: 0 | AL3: 0 | AM3: 0
A4: BEBAN GAS - RESTO | B4: INPUT SO HARIAN | C4: SO | D4: USAGE | E4: LPG 12KG | F4: SO | H4: TABUNG | I4: 0 | J4: 0 | K4: 0 | L4: 0 | M4: 0 | N4: 0 | O4: 0 | P4: 0 | Q4: 0 | R4: 0 | S4: 0 | T4: 0 | U4: 0 | V4: 0 | W4: 0 | X4: 0 | Y4: 0 | Z4: 0 | AA4: 0 | AB4: 0 | AC4: 0 | AD4: 0 | AE4: 0 | AF4: 0 | AG4: 0 | AH4: 0 | AI4: 0 | AJ4: 0 | AK4: 0 | AL4: 0 | AM4: 0
A5: BEBAN GAS - RESTO | B5: STOCK AWAL | C5: STOCK AWAL | D5: USAGE | E5: LPG 12KG | F5: STOK AWAL | H5: TABUNG | I5: 0 | J5: 0 | K5: 0 | L5: 0 | M5: 0 | N5: 0 | O5: 0 | P5: 0 | Q5: 0 | R5: 0 | S5: 0 | T5: 0 | U5: 0 | V5: 0 | W5: 0 | X5: 0 | Y5: 0 | Z5: 0 | AA5: 0 | AB5: 0 | AC5: 0 | AD5: 0 | AE5: 0 | AF5: 0 | AG5: 0 | AH5: 0 | AI5: 0 | AJ5: 0 | AK5: 0 | AL5: 0 | AM5: 0
A6: Beban ATK - Resto | B6: INPUT BARANG KELUAR | C6: BARANG KELUAR | D6: USAGE | E6: KERTAS THERMAL | F6: BARANG KELUAR | H6: PCS | I6: 0 | J6: 0 | K6: 0 | L6: 0 | M6: 0 | N6: 0 | O6: 0 | P6: 0 | Q6: 0 | R6: 0 | S6: 0 | T6: 0 | U6: 0 | V6: 0 | W6: 0 | X6: 0 | Y6: 0 | Z6: 0 | AA6: 0 | AB6: 0 | AC6: 0 | AD6: 0 | AE6: 0 | AF6: 0 | AG6: 0 | AH6: 0 | AI6: 0 | AJ6: 0 | AK6: 0 | AL6: 0 | AM6: 0
A7: Beban ATK - Resto | B7: INPUT BARANG MASUK | C7: BARANG MASUK | D7: USAGE | E7: KERTAS THERMAL | F7: BARANG MASUK | H7: PCS | I7: 0 | J7: 0 | K7: 0 | L7: 0 | M7: 0 | N7: 0 | O7: 0 | P7: 0 | Q7: 0 | R7: 50 | S7: 0 | T7: 0 | U7: 0 | V7: 0 | W7: 0 | X7: 0 | Y7: 0 | Z7: 0 | AA7: 0 | AB7: 0 | AC7: 0 | AD7: 0 | AE7: 0 | AF7: 0 | AG7: 0 | AH7: 0 | AI7: 0 | AJ7: 0 | AK7: 0 | AL7: 0 | AM7: 0
A8: Beban ATK - Resto | B8: INPUT SO HARIAN | C8: SO | D8: USAGE | E8: KERTAS THERMAL | F8: SO | H8: PCS | I8: 109 | J8: 112 | K8: 104 | L8: 143 | M8: 88 | N8: 84 | O8: 80 | P8: 83 | Q8: 83 | R8: 129 | S8: 122 | T8: 120 | U8: 116 | V8: 109 | W8: 0 | X8: 0 | Y8: 0 | Z8: 0 | AA8: 0 | AB8: 0 | AC8: 0 | AD8: 0 | AE8: 0 | AF8: 0 | AG8: 0 | AH8: 0 | AI8: 0 | AJ8: 0 | AK8: 0 | AL8: 0 | AM8: 0
A9: Beban ATK - Resto | B9: STOCK AWAL | C9: STOCK AWAL | D9: USAGE | E9: KERTAS THERMAL | F9: STOK AWAL | H9: PCS | I9: 120 | J9: 0 | K9: 0 | L9: 0 | M9: 0 | N9: 0 | O9: 0 | P9: 0 | Q9: 0 | R9: 0 | S9: 0 | T9: 0 | U9: 0 | V9: 0 | W9: 0 | X9: 0 | Y9: 0 | Z9: 0 | AA9: 0 | AB9: 0 | AC9: 0 | AD9: 0 | AE9: 0 | AF9: 0 | AG9: 0 | AH9: 0 | AI9: 0 | AJ9: 0 | AK9: 0 | AL9: 0 | AM9: 0
A10: Beban Kebersihan - Resto | B10: INPUT BARANG KELUAR | C10: BARANG KELUAR | D10: USAGE | E10: HAND GLOVE KARET | F10: BARANG KELUAR | H10: PCS | I10: 800 | J10: 0 | K10: 0 | L10: 0 | M10: 0 | N10: 0 | O10: 0 | P10: 0 | Q10: 0 | R10: 0 | S10: 0 | T10: 0 | U10: 0 | V10: 0 | W10: 0 | X10: 0 | Y10: 0 | Z10: 0 | AA10: 0 | AB10: 0 | AC10: 0 | AD10: 0 | AE10: 0 | AF10: 0 | AG10: 0 | AH10: 0 | AI10: 0 | AJ10: 0 | AK10: 0 | AL10: 0 | AM10: 0
A11: Beban Kebersihan - Resto | B11: INPUT BARANG KELUAR | C11: BARANG KELUAR | D11: USAGE | E11: HAND GLOVE PLASTIK | F11: BARANG KELUAR | H11: PCS | I11: 0 | J11: 0 | K11: 0 | L11: 0 | M11: 0 | N11: 0 | O11: 0 | P11: 0 | Q11: 0 | R11: 0 | S11: 0 | T11: 0 | U11: 0 | V11: 0 | W11: 0 | X11: 0 | Y11: 0 | Z11: 0 | AA11: 0 | AB11: 0 | AC11: 0 | AD11: 0 | AE11: 0 | AF11: 0 | AG11: 0 | AH11: 0 | AI11: 0 | AJ11: 0 | AK11: 0 | AL11: 0 | AM11: 0
A12: Beban Kebersihan - Resto | B12: INPUT BARANG KELUAR | C12: BARANG KELUAR | D12: USAGE | E12: HANDSANITIZER | F12: BARANG KELUAR | H12: JURIGEN | I12: 0 | J12: 0 | K12: 0 | L12: 0 | M12: 0 | N12: 0 | O12: 0 | P12: 0 | Q12: 0 | R12: 0 | S12: 0 | T12: 0 | U12: 0 | V12: 0 | W12: 0 | X12: 0 | Y12: 0 | Z12: 0 | AA12: 0 | AB12: 0 | AC12: 0 | AD12: 0 | AE12: 0 | AF12: 0 | AG12: 0 | AH12: 0 | AI12: 0 | AJ12: 0 | AK12: 0 | AL12: 0 | AM12: 0
A13: Beban Kebersihan - Resto | B13: INPUT BARANG KELUAR | C13: BARANG KELUAR | D13: USAGE | E13: HANDSOAP | F13: BARANG KELUAR | H13: JURIGEN | I13: 0 | J13: 0 | K13: 0 | L13: 0 | M13: 0 | N13: 0 | O13: 0 | P13: 0 | Q13: 0 | R13: 0 | S13: 0 | T13: 0 | U13: 0 | V13: 0 | W13: 0 | X13: 0 | Y13: 0 | Z13: 0 | AA13: 0 | AB13: 0 | AC13: 0 | AD13: 0 | AE13: 0 | AF13: 0 | AG13: 0 | AH13: 0 | AI13: 0 | AJ13: 0 | AK13: 0 | AL13: 0 | AM13: 0
... A274: Biaya Packaging - RESTO | B274: TRIAL PORSI | C274: TRIAL | D274: DEVIASI | E274: KLIP PE 4 X 6 | F274: TRIAL | H274: LEMBAR | I274: 0 | J274: 0 | K274: 0 | L274: 0 | M274: 0 | N274: 0 | O274: 0 | P274: 0 | Q274: 0 | R274: 0 | S274: 0 | T274: 0 | U274: 0 | V274: 0 | W274: 0 | X274: 0 | Y274: 0 | Z274: 0 | AA274: 0 | AB274: 0 | AC274: 0 | AD274: 0 | AE274: 0 | AF274: 0 | AG274: 0 | AH274: 0 | AI274: 0 | AJ274: 0 | AK274: 0 | AL274: 0 | AM274: 0
A275: Biaya Packaging - RESTO | B275: WASTE BAHAN DAN PACKAGING | C275: WASTE | D275: DEVIASI | E275: CUP 16 - BAKSO | F275: Alat/ Mesin | G275: CUP 16 - BAKSO Karena Alat/ Mesin | H275: PCS | I275: 0 | J275: 0 | K275: 0 | L275: 0 | M275: 0 | N275: 0 | O275: 0 | P275: 0 | Q275: 0 | R275: 0 | S275: 0 | T275: 0 | U275: 0 | V275: 0 | W275: 0 | X275: 0 | Y275: 0 | Z275: 0 | AA275: 0 | AB275: 0 | AC275: 0 | AD275: 0 | AE275: 0 | AF275: 0 | AG275: 0 | AH275: 0 | AI275: 0 | AJ275: 0 | AK275: 0 | AL275: 0 | AM275: 0
A276: Biaya Packaging - RESTO | B276: WASTE BAHAN DAN PACKAGING | C276: WASTE | D276: DEVIASI | E276: CUP 16 - BAKSO | F276: Handling | G276: CUP 16 - BAKSO Karena Handling | H276: PCS | I276: 0 | J276: 0 | K276: 0 | L276: 0 | M276: 0 | N276: 0 | O276: 0 | P276: 0 | Q276: 0 | R276: 0 | S276: 0 | T276: 0 | U276: 0 | V276: 0 | W276: 0 | X276: 0 | Y276: 0 | Z276: 0 | AA276: 0 | AB276: 0 | AC276: 0 | AD276: 0 | AE276: 0 | AF276: 0 | AG276: 0 | AH276: 0 | AI276: 0 | AJ276: 0 | AK276: 0 | AL276: 0 | AM276: 0
A277: Biaya Packaging - RESTO | B277: WASTE BAHAN DAN PACKAGING | C277: WASTE | D277: DEVIASI | E277: CUP 16 - BAKSO | F277: Kualitas Internal | G277: CUP 16 - BAKSO Karena Kualitas Internal | H277: PCS | I277: 0 | J277: 0 | K277: 0 | L277: 0 | M277: 0 | N277: 0 | O277: 0 | P277: 0 | Q277: 0 | R277: 0 | S277: 0 | T277: 0 | U277: 0 | V277: 0 | W277: 0 | X277: 0 | Y277: 0 | Z277: 0 | AA277: 0 | AB277: 0 | AC277: 0 | AD277: 0 | AE277: 0 | AF277: 0 | AG277: 0 | AH277: 0 | AI277: 0 | AJ277: 0 | AK277: 0 | AL277: 0 | AM277: 0
A278: Biaya Packaging - RESTO | B278: WASTE BAHAN DAN PACKAGING | C278: WASTE | D278: DEVIASI | E278: CUP 16 - BAKSO | F278: Over Stock | G278: CUP 16 - BAKSO Karena Over Stock | H278: PCS | I278: 0 | J278: 0 | K278: 0 | L278: 0 | M278: 0 | N278: 0 | O278: 0 | P278: 0 | Q278: 0 | R278: 0 | S278: 0 | T278: 0 | U278: 0 | V278: 0 | W278: 0 | X278: 0 | Y278: 0 | Z278: 0 | AA278: 0 | AB278: 0 | AC278: 0 | AD278: 0 | AE278: 0 | AF278: 0 | AG278: 0 | AH278: 0 | AI278: 0 | AJ278: 0 | AK278: 0 | AL278: 0 | AM278: 0
A279: Biaya Packaging - RESTO | B279: WASTE BAHAN DAN PACKAGING | C279: WASTE | D279: DEVIASI | E279: CUP SUNDAE - BAKSO | F279: Alat/ Mesin | G279: CUP SUNDAE - BAKSO Karena Alat/ Mesin | H279: PCS | I279: 0 | J279: 0 | K279: 0 | L279: 0 | M279: 0 | N279: 0 | O279: 0 | P279: 0 | Q279: 0 | R279: 0 | S279: 0 | T279: 0 | U279: 0 | V279: 0 | W279: 0 | X279: 0 | Y279: 0 | Z279: 0 | AA279: 0 | AB279: 0 | AC279: 0 | AD279: 0 | AE279: 0 | AF279: 0 | AG279: 0 | AH279: 0 | AI279: 0 | AJ279: 0 | AK279: 0 | AL279: 0 | AM279: 0
A280: Biaya Packaging - RESTO | B280: WASTE BAHAN DAN PACKAGING | C280: WASTE | D280: DEVIASI | E280: CUP SUNDAE - BAKSO | F280: Handling | G280: CUP SUNDAE - BAKSO Karena Handling | H280: PCS | I280: 0 | J280: 0 | K280: 0 | L280: 0 | M280: 0 | N280: 0 | O280: 0 | P280: 0 | Q280: 0 | R280: 0 | S280: 0 | T280: 0 | U280: 0 | V280: 0 | W280: 0 | X280: 0 | Y280: 0 | Z280: 0 | AA280: 0 | AB280: 0 | AC280: 0 | AD280: 0 | AE280: 0 | AF280: 0 | AG280: 0 | AH280: 0 | AI280: 0 | AJ280: 0 | AK280: 0 | AL280: 0 | AM280: 0
A281: Biaya Packaging - RESTO | B281: WASTE BAHAN DAN PACKAGING | C281: WASTE | D281: DEVIASI | E281: CUP SUNDAE - BAKSO | F281: Kualitas Internal | G281: CUP SUNDAE - BAKSO Karena Kualitas Internal | H281: PCS | I281: 0 | J281: 0 | K281: 0 | L281: 0 | M281: 0 | N281: 0 | O281: 0 | P281: 0 | Q281: 0 | R281: 0 | S281: 0 | T281: 0 | U281: 0 | V281: 0 | W281: 0 | X281: 0 | Y281: 0 | Z281: 0 | AA281: 0 | AB281: 0 | AC281: 0 | AD281: 0 | AE281: 0 | AF281: 0 | AG281: 0 | AH281: 0 | AI281: 0 | AJ281: 0 | AK281: 0 | AL281: 0 | AM281: 0
A282: Biaya Packaging - RESTO | B282: WASTE BAHAN DAN PACKAGING | C282: WASTE | D282: DEVIASI | E282: CUP SUNDAE - BAKSO | F282: Over Stock | G282: CUP SUNDAE - BAKSO Karena Over Stock | H282: PCS | I282: 0 | J282: 0 | K282: 0 | L282: 0 | M282: 0 | N282: 0 | O282: 0 | P282: 0 | Q282: 0 | R282: 0 | S282: 0 | T282: 0 | U282: 0 | V282: 0 | W282: 0 | X282: 0 | Y282: 0 | Z282: 0 | AA282: 0 | AB282: 0 | AC282: 0 | AD282: 0 | AE282: 0 | AF282: 0 | AG282: 0 | AH282: 0 | AI282: 0 | AJ282: 0 | AK282: 0 | AL282: 0 | AM282: 0
A283: Biaya Packaging - RESTO | B283: WASTE BAHAN DAN PACKAGING | C283: WASTE | D283: DEVIASI | E283: GARPU PLASTIK PS | F283: Alat/ Mesin | G283: GARPU PLASTIK PS Karena Alat/ Mesin | H283: PCS | I283: 0 | J283: 0 | K283: 0 | L283: 0 | M283: 0 | N283: 0 | O283: 0 | P283: 0 | Q283: 0 | R283: 0 | S283: 0 | T283: 0 | U283: 0 | V283: 0 | W283: 0 | X283: 0 | Y283: 0 | Z283: 0 | AA283: 0 | AB283: 0 | AC283: 0 | AD283: 0 | AE283: 0 | AF283: 0 | AG283: 0 | AH283: 0 | AI283: 0 | AJ283: 0 | AK283: 0 | AL283: 0 | AM283: 0
A284: Biaya Packaging - RESTO | B284: WASTE BAHAN DAN PACKAGING | C284: WASTE | D284: DEVIASI | E284: GARPU PLASTIK PS | F284: Handling | G284: GARPU PLASTIK PS Karena Handling | H284: PCS | I284: 0 | J284: 0 | K284: 0 | L284: 0 | M284: 0 | N284: 0 | O284: 0 | P284: 0 | Q284: 0 | R284: 0 | S284: 0 | T284: 0 | U284: 0 | V284: 0 | W284: 0 | X284: 0 | Y284: 0 | Z284: 0 | AA284: 0 | AB284: 0 | AC284: 0 | AD284: 0 | AE284: 0 | AF284: 0 | AG284: 0 | AH284: 0 | AI284: 0 | AJ284: 0 | AK284: 0 | AL284: 0 | AM284: 0
A285: Biaya Packaging - RESTO | B285: WASTE BAHAN DAN PACKAGING | C285: WASTE | D285: DEVIASI | E285: GARPU PLASTIK PS | F285: Kualitas Internal | G285: GARPU PLASTIK PS Karena Kualitas Internal | H285: PCS | I285: 0 | J285: 0 | K285: 0 | L285: 0 | M285: 0 | N285: 0 | O285: 0 | P285: 0 | Q285: 0 | R285: 0 | S285: 0 | T285: 0 | U285: 0 | V285: 0 | W285: 0 | X285: 0 | Y285: 0 | Z285: 0 | AA285: 0 | AB285: 0 | AC285: 0 | AD285: 0 | AE285: 0 | AF285: 0 | AG285: 0 | AH285: 0 | AI285: 0 | AJ285: 0 | AK285: 0 | AL285: 0 | AM285: 0
A286: Biaya Packaging - RESTO | B286: WASTE BAHAN DAN PACKAGING | C286: WASTE | D286: DEVIASI | E286: GARPU PLASTIK PS | F286: Over Stock | G286: GARPU PLASTIK PS Karena Over Stock | H286: PCS | I286: 0 | J286: 0 | K286: 0 | L286: 0 | M286: 0 | N286: 0 | O286: 0 | P286: 0 | Q286: 0 | R286: 0 | S286: 0 | T286: 0 | U286: 0 | V286: 0 | W286: 0 | X286: 0 | Y286: 0 | Z286: 0 | AA286: 0 | AB286: 0 | AC286: 0 | AD286: 0 | AE286: 0 | AF286: 0 | AG286: 0 | AH286: 0 | AI286: 0 | AJ286: 0 | AK286: 0 | AL286: 0 | AM286: 0
... A379: Biaya Packaging - RESTO | B379: WASTEPORSI DINEIN KARNAHANDLING | C379: WASTE | D379: DEVIASI | E379: PLASTIK HDPE 12 X 25 | F379: Handling | G379: PLASTIK HDPE 12 X 25 Karena Handling | H379: PCS | I379: 0 | J379: 0 | K379: 0 | L379: 0 | M379: 0 | N379: 0 | O379: 0 | P379: 0 | Q379: 0 | R379: 0 | S379: 0 | T379: 0 | U379: 0 | V379: 0 | W379: 0 | X379: 0 | Y379: 0 | Z379: 0 | AA379: 0 | AB379: 0 | AC379: 0 | AD379: 0 | AE379: 0 | AF379: 0 | AG379: 0 | AH379: 0 | AI379: 0 | AJ379: 0 | AK379: 0 | AL379: 0 | AM379: 0
A380: COM CONSUME - RESTO | B380: INPUT BARANG KELUAR | C380: BARANG KELUAR | D380: USAGE | E380: ARANG BAKARAN | F380: BARANG KELUAR | H380: GR | I380: 0 | J380: 0 | K380: 0 | L380: 0 | M380: 0 | N380: 0 | O380: 0 | P380: 0 | Q380: 0 | R380: 0 | S380: 0 | T380: 0 | U380: 0 | V380: 0 | W380: 0 | X380: 0 | Y380: 0 | Z380: 0 | AA380: 0 | AB380: 0 | AC380: 0 | AD380: 0 | AE380: 0 | AF380: 0 | AG380: 0 | AH380: 0 | AI380: 0 | AJ380: 0 | AK380: 0 | AL380: 0 | AM380: 0
A381: COM CONSUME - RESTO | B381: INPUT BARANG KELUAR | C381: BARANG KELUAR | D381: USAGE | E381: MINYAK GORENG - RESTO (v.20) | F381: BARANG KELUAR | H381: GR | I381: 0 | J381: 0 | K381: 0 | L381: 0 | M381: 0 | N381: 0 | O381: 0 | P381: 0 | Q381: 0 | R381: 0 | S381: 0 | T381: 0 | U381: 0 | V381: 0 | W381: 0 | X381: 0 | Y381: 0 | Z381: 0 | AA381: 0 | AB381: 0 | AC381: 0 | AD381: 0 | AE381: 0 | AF381: 0 | AG381: 0 | AH381: 0 | AI381: 0 | AJ381: 0 | AK381: 0 | AL381: 0 | AM381: 0
A382: COM CONSUME - RESTO | B382: INPUT BARANG MASUK | C382: BARANG MASUK | D382: USAGE | E382: ARANG BAKARAN | F382: BARANG MASUK | H382: GR | I382: 0 | J382: 0 | K382: 0 | L382: 0 | M382: 20000 | N382: 0 | O382: 0 | P382: 0 | Q382: 0 | R382: 0 | S382: 0 | T382: 0 | U382: 0 | V382: 0 | W382: 0 | X382: 0 | Y382: 0 | Z382: 0 | AA382: 0 | AB382: 0 | AC382: 0 | AD382: 0 | AE382: 0 | AF382: 0 | AG382: 0 | AH382: 0 | AI382: 0 | AJ382: 0 | AK382: 0 | AL382: 0 | AM382: 0
A383: COM CONSUME - RESTO | B383: INPUT BARANG MASUK | C383: BARANG MASUK | D383: USAGE | E383: MINYAK GORENG - RESTO (v.20) | F383: BARANG MASUK | H383: GR | I383: 0 | J383: 0 | K383: 0 | L383: 0 | M383: 0 | N383: 0 | O383: 0 | P383: 0 | Q383: 0 | R383: 0 | S383: 0 | T383: 0 | U383: 0 | V383: 194400 | W383: 0 | X383: 0 | Y383: 0 | Z383: 0 | AA383: 0 | AB383: 0 | AC383: 0 | AD383: 0 | AE383: 0 | AF383: 0 | AG383: 0 | AH383: 0 | AI383: 0 | AJ383: 0 | AK383: 0 | AL383: 0 | AM383: 0
A384: COM CONSUME - RESTO | B384: INPUT SO HARIAN | C384: SO | D384: USAGE | E384: ARANG BAKARAN | F384: SO | H384: GR | I384: 553860 | J384: 526460 | K384: 496270 | L384: 465440 | M384: 435457 | N384: 395933 | O384: 371602 | P384: 344455 | Q384: 311391 | R384: 279660 | S384: 250145 | T384: 226499 | U384: 20353 | V384: 153000 | W384: 0 | X384: 0 | Y384: 0 | Z384: 0 | AA384: 0 | AB384: 0 | AC384: 0 | AD384: 0 | AE384: 0 | AF384: 0 | AG384: 0 | AH384: 0 | AI384: 0 | AJ384: 0 | AK384: 0 | AL384: 0 | AM384: 0
A385: COM CONSUME - RESTO | B385: INPUT SO HARIAN | C385: SO | D385: USAGE | E385: MINYAK GORENG - RESTO (v.20) | F385: SO | H385: GR | I385: 619600 | J385: 586080 | K385: 647450 | L385: 623740 | M385: 523260 | N385: 594025 | O385: 545950 | P385: 506323 | Q385: 511940 | R385: 432055 | S385: 443290 | T385: 155350 | U385: 399250 | V385: 614520 | W385: 0 | X385: 0 | Y385: 0 | Z385: 0 | AA385: 0 | AB385: 0 | AC385: 0 | AD385: 0 | AE385: 0 | AF385: 0 | AG385: 0 | AH385: 0 | AI385: 0 | AJ385: 0 | AK385: 0 | AL385: 0 | AM385: 0
A386: COM CONSUME - RESTO | B386: STOCK AWAL | C386: STOCK AWAL | D386: USAGE | E386: ARANG BAKARAN | F386: STOK AWAL | H386: GR | I386: 585017 | J386: 0 | K386: 0 | L386: 0 | M386: 0 | N386: 0 | O386: 0 | P386: 0 | Q386: 0 | R386: 0 | S386: 0 | T386: 0 | U386: 0 | V386: 0 | W386: 0 | X386: 0 | Y386: 0 | Z386: 0 | AA386: 0 | AB386: 0 | AC386: 0 | AD386: 0 | AE386: 0 | AF386: 0 | AG386: 0 | AH386: 0 | AI386: 0 | AJ386: 0 | AK386: 0 | AL386: 0 | AM386: 0
A387: COM CONSUME - RESTO | B387: STOCK AWAL | C387: STOCK AWAL | D387: USAGE | E387: MINYAK GORENG - RESTO (v.20) | F387: STOK AWAL | H387: GR | I387: 707480 | J387: 0 | K387: 0 | L387: 0 | M387: 0 | N387: 0 | O387: 0 | P387: 0 | Q387: 0 | R387: 0 | S387: 0 | T387: 0 | U387: 0 | V387: 0 | W387: 0 | X387: 0 | Y387: 0 | Z387: 0 | AA387: 0 | AB387: 0 | AC387: 0 | AD387: 0 | AE387: 0 | AF387: 0 | AG387: 0 | AH387: 0 | AI387: 0 | AJ387: 0 | AK387: 0 | AL387: 0 | AM387: 0
A388: COM CONSUME - RESTO | B388: SUSUT | C388: SUSUT | D388: USAGE | E388: MINYAK GORENG - RESTO (v.20) | F388: SUSUT | H388: GR | I388: 0 | J388: 0 | K388: 0 | L388: 0 | M388: 0 | N388: 0 | O388: 0 | P388: 0 | Q388: 0 | R388: 0 | S388: 0 | T388: 0 | U388: 0 | V388: 0 | W388: 0 | X388: 0 | Y388: 0 | Z388: 0 | AA388: 0 | AB388: 0 | AC388: 0 | AD388: 0 | AE388: 0 | AF388: 0 | AG388: 0 | AH388: 0 | AI388: 0 | AJ388: 0 | AK388: 0 | AL388: 0 | AM388: 0
A389: COM CONSUME - RESTO | B389: TRIAL BAHAN | C389: TRIAL | D389: USAGE | E389: MINYAK GORENG - RESTO (v.20) | F389: TRIAL | H389: GR | I389: 0 | J389: 0 | K389: 0 | L389: 0 | M389: 0 | N389: 0 | O389: 0 | P389: 0 | Q389: 0 | R389: 0 | S389: 0 | T389: 0 | U389: 0 | V389: 0 | W389: 0 | X389: 0 | Y389: 0 | Z389: 0 | AA389: 0 | AB389: 0 | AC389: 0 | AD389: 0 | AE389: 0 | AF389: 0 | AG389: 0 | AH389: 0 | AI389: 0 | AJ389: 0 | AK389: 0 | AL389: 0 | AM389: 0
A390: COM CONSUME - RESTO | B390: WASTE BAHAN DAN PACKAGING | C390: WASTE | D390: USAGE | E390: MINYAK GORENG - RESTO (v.20) | F390: Alat/ Mesin | G390: MINYAK GORENG - RESTO (v.20) Karena Alat/ Mesin | H390: GR | I390: 0 | J390: 0 | K390: 0 | L390: 0 | M390: 0 | N390: 0 | O390: 0 | P390: 0 | Q390: 0 | R390: 0 | S390: 0 | T390: 0 | U390: 0 | V390: 0 | W390: 0 | X390: 0 | Y390: 0 | Z390: 0 | AA390: 0 | AB390: 0 | AC390: 0 | AD390: 0 | AE390: 0 | AF390: 0 | AG390: 0 | AH390: 0 | AI390: 0 | AJ390: 0 | AK390: 0 | AL390: 0 | AM390: 0
A391: COM CONSUME - RESTO | B391: WASTE BAHAN DAN PACKAGING | C391: WASTE | D391: USAGE | E391: MINYAK GORENG - RESTO (v.20) | F391: Handling | G391: MINYAK GORENG - RESTO (v.20) Karena Handling | H391: GR | I391: 0 | J391: 0 | K391: 0 | L391: 0 | M391: 0 | N391: 0 | O391: 0 | P391: 0 | Q391: 0 | R391: 0 | S391: 0 | T391: 0 | U391: 0 | V391: 0 | W391: 0 | X391: 0 | Y391: 0 | Z391: 0 | AA391: 0 | AB391: 0 | AC391: 0 | AD391: 0 | AE391: 0 | AF391: 0 | AG391: 0 | AH391: 0 | AI391: 0 | AJ391: 0 | AK391: 0 | AL391: 0 | AM391: 0
A392: COM CONSUME - RESTO | B392: WASTE BAHAN DAN PACKAGING | C392: WASTE | D392: USAGE | E392: MINYAK GORENG - RESTO (v.20) | F392: Kualitas Internal | G392: MINYAK GORENG - RESTO (v.20) Karena Kualitas Internal | H392: GR | I392: 0 | J392: 0 | K392: 0 | L392: 0 | M392: 0 | N392: 0 | O392: 0 | P392: 0 | Q392: 0 | R392: 0 | S392: 0 | T392: 0 | U392: 0 | V392: 0 | W392: 0 | X392: 0 | Y392: 0 | Z392: 0 | AA392: 0 | AB392: 0 | AC392: 0 | AD392: 0 | AE392: 0 | AF392: 0 | AG392: 0 | AH392: 0 | AI392: 0 | AJ392: 0 | AK392: 0 | AL392: 0 | AM392: 0
...

Sheet WASTE BAHAN dan PACKAGING
A1: NAMA BARANG | B1: KETERANGAN | C1: PENYEBAB TERJADINYA WASTE | D1: SATUAN | E1: KONVERSI | F1: 1 | G1: 2 | H1: 3 | I1: 4 | J1: 5 | K1: 6 | L1: 7 | M1: 8 | N1: 9 | O1: 10 | P1: 11 | Q1: 12 | R1: 13 | S1: 14 | T1: 15 | U1: 16 | V1: 17 | W1: 18 | X1: 19 | Y1: 20 | Z1: 21 | AA1: 22 | AB1: 23 | AC1: 24 | AD1: 25 | AE1: 26 | AF1: 27 | AG1: 28 | AH1: 29 | AI1: 30 | AJ1: 31
A2: ADONAN GORENG MEKAR | B2: Over Stock | C2: ADONAN GORENG MEKAR Karena Over Stock | D2: GR | E2: 1 | F2: 0 | G2: 0 | H2: 0 | I2: 0 | J2: 0 | K2: 0 | L2: 0 | M2: 0 | N2: 0 | P2: 0 | Q2: 0 | R2: 0 | S2: 0
A3: ADONAN GORENG MEKAR | B3: Handling | C3: ADONAN GORENG MEKAR Karena Handling | D3: GR | E3: 1 | F3: 0 | G3: 0 | H3: 0 | I3: 0 | J3: 0 | K3: 0 | L3: 0 | M3: 0 | N3: 0 | P3: 0 | Q3: 0 | R3: 0 | S3: 0
A4: ADONAN GORENG MEKAR | B4: Kualitas Internal | C4: ADONAN GORENG MEKAR Karena Kualitas Internal | D4: GR | E4: 1 | F4: 0 | G4: 0 | H4: 0 | I4: 0 | J4: 0 | K4: 0 | L4: 0 | M4: 0 | N4: 0 | P4: 0 | Q4: 0 | R4: 0 | S4: 0
A5: ADONAN GORENG MEKAR | B5: Alat/ Mesin | C5: ADONAN GORENG MEKAR Karena Alat/ Mesin | D5: GR | E5: 1 | F5: 0
F6: 0
A7: AIR MINERAL BOTOL (V.20) | B7: Over Stock | C7: AIR MINERAL BOTOL (V.20) Karena Over Stock | D7: BOTOL | E7: 1 | F7: 0 | G7: 0 | H7: 0 | I7: 0 | J7: 0 | K7: 0 | L7: 0 | M7: 0 | N7: 0 | O7: 0 | P7: 0 | Q7: 0 | R7: 0 | S7: 0
A8: AIR MINERAL BOTOL (V.20) | B8: Handling | C8: AIR MINERAL BOTOL (V.20) Karena Handling | D8: BOTOL | E8: 1 | F8: 0 | G8: 0 | H8: 0 | I8: 0 | J8: 0 | K8: 0 | L8: 0 | M8: 0 | N8: 0 | O8: 0 | P8: 0 | Q8: 0 | R8: 0 | S8: 0
A9: AIR MINERAL BOTOL (V.20) | B9: Kualitas Eksternal | C9: AIR MINERAL BOTOL (V.20) Karena Kualitas Eksternal | D9: BOTOL | E9: 1 | F9: 0 | G9: 0 | H9: 0 | I9: 0 | J9: 0 | K9: 0 | L9: 0 | M9: 0 | N9: 0 | O9: 0 | P9: 0 | Q9: 0 | R9: 0 | S9: 0
A10: AIR MINERAL BOTOL (V.20) | B10: Alat/ Mesin | C10: AIR MINERAL BOTOL (V.20) Karena Alat/ Mesin | D10: BOTOL | E10: 1 | F10: 0 | G10: 0 | H10: 0 | I10: 0 | J10: 0 | K10: 0 | L10: 0 | M10: 0 | N10: 0 | P10: 0 | Q10: 0 | R10: 0 | S10: 0
F11: 0
A12: AYAM KECAP | B12: Over Stock | C12: AYAM KECAP Karena Over Stock | D12: GR | E12: 1 | F12: 0 | G12: 0 | H12: 0 | I12: 0 | J12: 0 | K12: 0 | L12: 0 | M12: 0 | N12: 0 | O12: 0 | P12: 0 | Q12: 0 | R12: 0 | S12: 0
A13: AYAM KECAP | B13: Handling | C13: AYAM KECAP Karena Handling | D13: GR | E13: 1 | F13: 0 | G13: 0 | H13: 0 | I13: 0 | J13: 0 | K13: 0 | L13: 0 | M13: 0 | N13: 0 | O13: 0 | P13: 0 | Q13: 0 | R13: 0 | S13: 0
A14: AYAM KECAP | B14: Kualitas Internal | C14: AYAM KECAP Karena Kualitas Internal | D14: GR | E14: 1 | F14: 0 | G14: 0 | H14: 0 | I14: 0 | J14: 0 | K14: 0 | L14: 0 | M14: 0 | N14: 0 | O14: 0 | P14: 0 | Q14: 0 | R14: 0 | S14: 0
A15: AYAM KECAP | B15: Alat/ Mesin | C15: AYAM KECAP Karena Alat/ Mesin | D15: GR | E15: 1 | F15: 0 | O15: 0
F16: 0
A17: BAKSO HALUS | B17: Over Stock | C17: BAKSO HALUS Karena Over Stock | D17: PCS | E17: 1 | F17: 0 | G17: 0 | H17: 0 | I17: 0 | J17: 0 | K17: 0 | L17: 0 | M17: 0 | N17: 0 | O17: 0 | P17: 0 | Q17: 0 | R17: 0 | S17: 0
A18: BAKSO HALUS | B18: Handling | C18: BAKSO HALUS Karena Handling | D18: PCS | E18: 1 | F18: 9 | G18: 21 | H18: 10 | I18: 31 | J18: 13 | K18: 5 | L18: 124 | M18: 145 | N18: 26 | O18: 0 | P18: 26 | Q18: 16 | R18: 7 | S18: 14
A19: BAKSO HALUS | B19: Kualitas Internal | C19: BAKSO HALUS Karena Kualitas Internal | D19: PCS | E19: 1 | F19: 32 | G19: 15 | H19: 46 | I19: 45 | J19: 11 | K19: 38 | L19: 21 | M19: 32 | N19: 25 | O19: 0 | P19: 20 | Q19: 23 | R19: 28 | S19: 36
A20: BAKSO HALUS | B20: Alat/ Mesin | C20: BAKSO HALUS Karena Alat/ Mesin | D20: PCS | E20: 1 | F20: 0
F21: 0
A22: BAKSO HALUS | B22: Over Stock | C22: BAKSO HALUS Lv 0 (Ada Bumbu Bakar) Karena Over Stock | D22: PCS | E22: 1 | F22: 0 | G22: 0 | H22: 0 | I22: 0 | J22: 0 | K22: 0 | L22: 0 | M22: 0 | N22: 0 | O22: 0 | P22: 0 | Q22: 0 | R22: 0 | S22: 0
A23: BAKSO HALUS | B23: Handling | C23: BAKSO HALUS Lv 0 (Ada Bumbu Bakar) Karena Handling | D23: PCS | E23: 1 | F23: 9 | G23: 16 | H23: 6 | I23: 11 | J23: 46 | K23: 2 | L23: 4 | M23: 22 | N23: 23 | O23: 76 | P23: 10 | Q23: 44 | R23: 34 | S23: 34
A24: BAKSO HALUS | B24: Kualitas Internal | C24: BAKSO HALUS Lv 0 (Ada Bumbu Bakar) Karena Kualitas Internal | D24: PCS | E24: 1 | F24: 32 | G24: 0 | H24: 0 | I24: 0 | J24: 0 | K24: 0 | L24: 0 | M24: 0 | N24: 0 | O24: 34 | P24: 0 | Q24: 0 | R24: 0 | S24: 0
A25: BAKSO HALUS | B25: Alat/ Mesin | C25: BAKSO HALUS Lv 0 (Ada Bumbu Bakar) Karena Alat/ Mesin | D25: PCS | E25: 1 | F25: 0 | G25: 0 | H25: 0 | I25: 0 | J25: 0 | K25: 0 | L25: 0 | M25: 0 | N25: 0 | P25: 0 | Q25: 0 | R25: 0 | S25: 0
F26: 0 | G26: 0 | H26: 0 | I26: 0 | J26: 0 | K26: 0 | L26: 0 | M26: 0 | N26: 0 | P26: 0 | Q26: 0 | R26: 0 | S26: 0
A27: BAKSO HALUS | B27: Over Stock | C27: BAKSO HALUS Lv 2 (Ada Bumbu Bakar) Karena Over Stock | D27: PCS | E27: 1 | F27: 0 | G27: 0 | H27: 0 | I27: 0 | J27: 0 | K27: 0 | L27: 0 | M27: 0 | N27: 0 | O27: 0 | P27: 0 | Q27: 0 | R27: 0 | S27: 0
A28: BAKSO HALUS | B28: Handling | C28: BAKSO HALUS Lv 2 (Ada Bumbu Bakar) Karena Handling | D28: PCS | E28: 1 | F28: 9 | G28: 0 | H28: 0 | I28: 0 | J28: 0 | K28: 0 | L28: 0 | M28: 0 | N28: 0 | O28: 18 | P28: 0 | Q28: 0 | R28: 0 | S28: 0
A29: BAKSO HALUS | B29: Kualitas Internal | C29: BAKSO HALUS Lv 2 (Ada Bumbu Bakar) Karena Kualitas Internal | D29: PCS | E29: 1 | F29: 32 | G29: 0 | H29: 0 | I29: 0 | J29: 0 | K29: 0 | L29: 0 | M29: 0 | N29: 0 | O29: 0 | P29: 0 | Q29: 0 | R29: 0 | S29: 0
A30: BAKSO HALUS | B30: Alat/ Mesin | C30: BAKSO HALUS Lv 2 (Ada Bumbu Bakar) Karena Alat/ Mesin | D30: PCS | E30: 1 | F30: 0 | G30: 0 | H30: 0 | I30: 0 | J30: 0 | K30: 0 | L30: 0 | M30: 0 | N30: 0 | O30: 0 | P30: 0 | Q30: 0 | R30: 0 | S30: 0
F31: 0 | G31: 0 | H31: 0 | I31: 0 | J31: 0 | K31: 0 | L31: 0 | M31: 0 | N31: 0 | O31: 0 | P31: 0 | Q31: 0 | R31: 0 | S31: 0
